Workbook
Name adhesion: #REF!

Sheet Perfil da Organização
B2: Lei Geral de Proteção de Dados (LGPD)
B5: Perfil da Organização
B6: Nome: | D6: Empresa Beta | G6: DPO (Data Protection Officer)
B7: Lucro anual estimado | G7: Não
B8: Setor de Atuação | G8: Estrutura Organizacional do DPO (Papéis estabelecidos)
B9: Região(ões) de operação: | G9: Não
B10: Controlador ou Operador | G10: Quais dos processos abaixo estão implementados ?
B11: Orçamento de proteção de dados para os próximos 12 meses? | G11: N | H11: Privacy by Design | I11: N | J11: Gestão de incidentes de privacidade
G12: N | H12: DPIA (Data Protection & Impact Assessment) | I12: S | J12: Descrição de bases legais para legitimação
B13: Existem outros departamentos com orçamento de proteção de dados? | G13: N | H13: Processo para gestão de petição de titulares | I13: N | J13: Descrição de períodos de retenção dos dados pessoais
G14: N | H14: Políticas e normas de privacidade | I14: N | J14: Segurança da Informação e Criptografia
B15: Orçamento anual | G15: Principais stakeholders
B16: Total
B17: Investimento
B18: Despesas operacionais
B20: Obs: Alguns campos não precisam ser preenchidos em caso de Instituições Públicas | H20: Ex.: Lucro estimado

Sheet Aplicabilidade
B2: Aplicabilidade
B5: Art. 3º Esta Lei aplica-se a qualquer operação de tratamento realizada por pessoa natural ou por pessoa jurídica de direito público ou privado, independentemente do meio, do país de sua sede ou do país onde estejam localizados os dados, desde que:
B6: I – a operação de tratamento seja realizada no território nacional; II – a atividade de tratamento tenha por objetivo a oferta ou o fornecimento de bens ou serviços ou o tratamento de dados de indivíduos localizados no território nacional; III – os dados pessoais objeto do tratamento tenham sido coletados no território nacional. § 1º Consideram-se coletados no território nacional os dados pessoais cujo titular nele se encontre no momento da coleta. § 2º Excetua-se do disposto no inciso I deste artigo o tratamento de dados previsto no inciso III do caput do art. 4º desta Lei.
B8: Art. 4º Esta Lei não se aplica ao tratamento de dados pessoais:
B9: I – realizado por pessoa natural para fins exclusivamente particulares e não econômicos;
B10: II – realizado para fins exclusivamente:
B11: a) jornalísticos;
B12: b) artísticos;
B13: c) acadêmicos, aplicando-se a esta hipótese os arts. 13 e 17 desta Lei;
B14: d) de segurança pública;
B15: e) de defesa nacional;
B16: f) de segurança do Estado;
... B20: b) sejam objeto de transferência internacional de dados com outro país que não o de proveniência, desde que o país de proveniência proporcione grau de proteção de dados pessoais adequado ao previsto nesta Lei.

Sheet Conceitos
B2: Conceitos
B4: Conceitos adotados pela Lei Geral de Proteção de Dados conforme o Artigo 5 da LGPD:
B5: Dado Pessoal
B6: Informação relacionada à pessoa natural identificada ou identificável
B8: Dado Pessoal Sensível
B9: Dado pessoal sobre origem racial ou étnica, convicção religiosa, opinião política, filiação a sindicato ou a organização de caráter religioso, filosófico ou político, saúde, vida sexual, genética ou biometria, quando vinculado a pessoa natural
B11: Banco de Dados
B12: Conjunto estruturado de dados pessoais, estabelecido em um ou em vários locais, em suporte eletrônico ou físico
B14: Dado Anonimizado
B15: Dado relativo a titular que não possa ser identificado, utilizando-se meios técnicos razoáveis e disponíveis na ocasião de seu tratamento
B17: Titular
B18: A pessoa natural a quem se referem os dados pessoais que são objeto de tratamento
... B60: Documentação do responsável que contém a descrição dos processos de tratamento de dados pessoais que podem gerar riscos às liberdades civis e aos direitos fundamentais, bem como medidas, salvaguardas e mecanismos de mitigação de risco

Sheet Controles
B2: Matriz de Controles e Avaliação de Gaps
B5: Controle | C5: Domínio | D5: Instruções | E5: Questionamentos | F5: Artigo | G5: Capítulo | H5: Cenário Atual | I5: Mapeamento | J5: Aderência | K5: Ponto de Melhoria
B7: 1 | C7: Tratamento dos dados pessoais | D7: Descrever | E7: Quais as principais atividades de tratamento de dados pessoais realizadas pela organização e, em linhas gerais, como tais atividades são realizadas? | F7: Art. 5º Para os fins desta Lei, considera-se: I - dado pessoal: informação relacionada a pessoa natural identificada ou identificável; X - tratamento: toda operação realizada com dados pessoais, como as que se referem a coleta, produção, recepção, classificação, utilização, acesso, reprodução, transmissão, distribuição, processamento, arquivamento, armazenamento, eliminação, avaliação ou controle da informação, modificação, comunicação, transferência, difusão ou extração. | G7: CAPÍTULO I - DISPOSIÇÕES PRELIMINARES | H7: A Empresa Beta realiza o tratamento de dados para prestação de serviços aos seus clientes, bem como para gestão interna de seus colaboradores. | I7: Em andamento | J7: Parcialmente aderente | K7: Adequar o tratamento de dados pessoais as diretrizes da LGPD (definição das bases legais)
B8: 2 | C8: Tratamento dos dados pessoais sensíveis | D8: S/N | E8: A organização realiza algum tipo de tratamento de dado pessoal sensível? | F8: Art. 5º Para os fins desta Lei, considera-se: II - dado pessoal sensível: dado pessoal sobre origem racial ou étnica, convicção religiosa, opinião política, filiação a sindicato ou a organização de caráter religioso, filosófico ou político, dado referente à saúde ou à vida sexual, dado genético ou biométrico, quando vinculado a uma pessoa natural; X - tratamento: toda operação realizada com dados pessoais, como as que se referem a coleta, produção, recepção, classificação, utilização, acesso, reprodução, transmissão, distribuição, processamento, arquivamento, armazenamento, eliminação, avaliação ou controle da informação, modificação, comunicação, transferência, difusão ou extração. | G8: CAPÍTULO I - DISPOSIÇÕES PRELIMINARES | H8: Sim | I8: Em andamento | J8: Parcialmente aderente | K8: Adequar o tratamento de dados pessoais sensíveis as diretrizes da LGPD (definição das bases legais)
B9: 3 | C9: Tratamento dos dados pessoais sensíveis | D9: Se a pergunta anterior for Sim | E9: Quais as principais atividades de tratamento de dados pessoais sensíveis realizadas pela organização e, em linhas gerais, como tais atividades são realizadas? | F9: Art. 5º Para os fins desta Lei, considera-se: II - dado pessoal sensível: dado pessoal sobre origem racial ou étnica, convicção religiosa, opinião política, filiação a sindicato ou a organização de caráter religioso, filosófico ou político, dado referente à saúde ou à vida sexual, dado genético ou biométrico, quando vinculado a uma pessoa natural; X - tratamento: toda operação realizada com dados pessoais, como as que se referem a coleta, produção, recepção, classificação, utilização, acesso, reprodução, transmissão, distribuição, processamento, arquivamento, armazenamento, eliminação, avaliação ou controle da informação, modificação, comunicação, transferência, difusão ou extração. | G9: CAPÍTULO I - DISPOSIÇÕES PRELIMINARES | H9: São tratados dados pessoais sensíveis para a diversidade na empresa e uso de imagem de colaboradores. | I9: Em andamento | J9: Parcialmente aderente | K9: Adequar o tratamento de dados pessoais sensíveis as diretrizes da LGPD (definição das bases legais)
B10: 4 | C10: Tratamento dos dados pessoais | D10: S/N | E10: As operações de tratamento de dados pessoais são realizadas com base na boa fé e em algum dos princípios de privacidade listados abaixo? | F10: Art. 6º As atividades de tratamento de dados pessoais deverão observar a boa-fé e os seguintes princípios: I – finalidade: realização do tratamento para propósitos legítimos, específicos, explícitos e informados ao titular, sem possibilidade de tratamento posterior de forma incompatível com esses propósitos; II – adequação: compatibilidade do tratamento com as finalidades informadas ao titular, de acordo com o contexto do tratamento; III – necessidade: limitação do tratamento ao mínimo necessário para a realização de suas finalidades, com a utilização de dados pertinentes, proporcionais e não excessivos em relação às finalidades do tratamento; IV – livre acesso: garantia, aos titulares, de consulta facilitada e gratuita sobre a forma e a duração do tratamento, bem como sobre a integralidade de seus dados pessoais; V – qualidade dos dados: garantia, aos titulares, de exatidão, clareza, relevância e atualização dos dados, de acordo com a necessidade e para o cumprimento da finalidade de seu tratamento; VI – transparência: garantia, aos titulares, de informações claras, precisas e facilmente acessíveis sobre a realização do tratamento e os respectivos agentes de tratamento, observados os segredos comercial e industrial; VII – segurança: utilização de medidas técnicas e administrativas aptas a proteger os dados pessoais de acessos não autorizados e de eventos acidentais ou ilícitos de destruição, perda, alteração, comunicação ou difusão; VIII – prevenção: adoção de medidas para prevenir a ocorrência de danos em virtude do tratamento de dados pessoais; IX – não discriminação: impossibilidade de realização do tratamento para fins discriminatórios ilícitos ou abusivos; X – responsabilização e prestação de contas: demonstração, pelo agente, da adoção de medidas eficazes e capazes de comprovar a observância e o cumprimento das normas de proteção de dados pessoais e, inclusive, da eficácia dessas medidas. | G10: CAPÍTULO I - DISPOSIÇÕES PRELIMINARES | H10: Parcialmente.
D11: Checkbox | E11: I – finalidade: realização do tratamento para propósitos legítimos, específicos, explícitos e informados ao titular, sem possibilidade de tratamento posterior de forma incompatível com esses propósitos; | I11: Em andamento | J11: Parcialmente aderente | K11: Revisão de Políticas para conformidade com o príncipio.
E12: II – adequação: compatibilidade do tratamento com as finalidades informadas ao titular, de acordo com o contexto do tratamento; | I12: Em andamento | J12: Parcialmente aderente | K12: Revisão de Políticas para conformidade com o príncipio.
E13: III – necessidade: limitação do tratamento ao mínimo necessário para a realização de suas finalidades, com a utilização de dados pertinentes, proporcionais e não excessivos em relação às finalidades do tratamento; | I13: Em andamento | J13: Parcialmente aderente | K13: Revisão de Políticas para conformidade com o príncipio.
E14: IV – livre acesso: garantia, aos titulares, de consulta facilitada e gratuita sobre a forma e a duração do tratamento, bem como sobre a integralidade de seus dados pessoais; | I14: Em andamento | J14: Parcialmente aderente | K14: Indicação de um canal de contato para possibilitar ao titular exercer os seus direitos
E15: V – qualidade dos dados: garantia, aos titulares, de exatidão, clareza, relevância e atualização dos dados, de acordo com a necessidade e para o cumprimento da finalidade de seu tratamento; | I15: Em andamento | J15: Parcialmente aderente | K15: Indicação de um canal de contato para possibilitar ao titular exercer os seus direitos
E16: VI – transparência: garantia, aos titulares, de informações claras, precisas e facilmente acessíveis sobre a realização do tratamento e os respectivos agentes de tratamento, observados os segredos comercial e industrial; | I16: Em andamento | J16: Parcialmente aderente | K16: Revisão de Políticas para conformidade com o príncipio.
E17: VII – segurança: utilização de medidas técnicas e administrativas aptas a proteger os dados pessoais de acessos não autorizados e de eventos acidentais ou ilícitos de destruição, perda, alteração, comunicação ou difusão; | I17: Em andamento | J17: Parcialmente aderente | K17: Necessário adequar as Políticas internas e externas e os processos de Tratamento de Dados Pessoais da Empresa Beta para atender aos príncipios da LGPD.
E18: VIII – prevenção: adoção de medidas para prevenir a ocorrência de danos em virtude do tratamento de dados pessoais; | I18: Em andamento | J18: Parcialmente aderente | K18: Necessário adequar as Políticas internas e externas e os processos de Tratamento de Dados Pessoais da Empresa Beta para atender aos príncipios da LGPD.
E19: IX – não discriminação: impossibilidade de realização do tratamento para fins discriminatórios ilícitos ou abusivos; | I19: Em andamento | J19: Não aderente | K19: Avaliar a questão de realização de background chack pela Empresa Beta para contratacão de novos colaboradores.
E20: X – responsabilização e prestação de contas: demonstração, pelo agente, da adoção de medidas eficazes e capazes de comprovar a observância e o cumprimento das normas de proteção de dados pessoais e, inclusive, da eficácia dessas medidas. | I20: Em andamento | J20: Não aderente | K20: A Empresa Beta deverá demonstrar por meio de politicas, listas de realização de treinamentos, e outros documentos que está em processo de adequação à LGPD.
B21: 5 | C21: Privacy By Design | D21: S/N | E21: A organização possui um processo de Privacy by Design? | F21: Art. 6º As atividades de tratamento de dados pessoais deverão observar a boa-fé e os seguintes princípios: I – finalidade: realização do tratamento para propósitos legítimos, específicos, explícitos e informados ao titular, sem possibilidade de tratamento posterior de forma incompatível com esses propósitos; II – adequação: compatibilidade do tratamento com as finalidades informadas ao titular, de acordo com o contexto do tratamento; III – necessidade: limitação do tratamento ao mínimo necessário para a realização de suas finalidades, com a utilização de dados pertinentes, proporcionais e não excessivos em relação às finalidades do tratamento; IV – livre acesso: garantia, aos titulares, de consulta facilitada e gratuita sobre a forma e a duração do tratamento, bem como sobre a integralidade de seus dados pessoais; V – qualidade dos dados: garantia, aos titulares, de exatidão, clareza, relevância e atualização dos dados, de acordo com a necessidade e para o cumprimento da finalidade de seu tratamento; VI – transparência: garantia, aos titulares, de informações claras, precisas e facilmente acessíveis sobre a realização do tratamento e os respectivos agentes de tratamento, observados os segredos comercial e industrial; VII – segurança: utilização de medidas técnicas e administrativas aptas a proteger os dados pessoais de acessos não autorizados e de eventos acidentais ou ilícitos de destruição, perda, alteração, comunicação ou difusão; VIII – prevenção: adoção de medidas para prevenir a ocorrência de danos em virtude do tratamento de dados pessoais; IX – não discriminação: impossibilidade de realização do tratamento para fins discriminatórios ilícitos ou abusivos; X – responsabilização e prestação de contas: demonstração, pelo agente, da adoção de medidas eficazes e capazes de comprovar a observância e o cumprimento das normas de proteção de dados pessoais e, inclusive, da eficácia dessas medidas. | G21: CAPÍTULO I - DISPOSIÇÕES PRELIMINARES | H21: Não. | I21: Não iniciado | J21: Não aderente | K21: Ao desenvolver um novo produto ou serviço a Empresa Beta deverá avaliar as diretrizes da LGPD, realizando o processo de Privacy by Design.
D22: Se a pergunta anterior for Sim S/N | E22: O processo de Privacy by Design considera o princípio da boa-fé e os 10 princípios de privacidade? | F22: Art. 6º As atividades de tratamento de dados pessoais deverão observar a boa-fé e os seguintes princípios: I – finalidade: realização do tratamento para propósitos legítimos, específicos, explícitos e informados ao titular, sem possibilidade de tratamento posterior de forma incompatível com esses propósitos; II – adequação: compatibilidade do tratamento com as finalidades informadas ao titular, de acordo com o contexto do tratamento; III – necessidade: limitação do tratamento ao mínimo necessário para a realização de suas finalidades, com a utilização de dados pertinentes, proporcionais e não excessivos em relação às finalidades do tratamento; IV – livre acesso: garantia, aos titulares, de consulta facilitada e gratuita sobre a forma e a duração do tratamento, bem como sobre a integralidade de seus dados pessoais; V – qualidade dos dados: garantia, aos titulares, de exatidão, clareza, relevância e atualização dos dados, de acordo com a necessidade e para o cumprimento da finalidade de seu tratamento; VI – transparência: garantia, aos titulares, de informações claras, precisas e facilmente acessíveis sobre a realização do tratamento e os respectivos agentes de tratamento, observados os segredos comercial e industrial; VII – segurança: utilização de medidas técnicas e administrativas aptas a proteger os dados pessoais de acessos não autorizados e de eventos acidentais ou ilícitos de destruição, perda, alteração, comunicação ou difusão; VIII – prevenção: adoção de medidas para prevenir a ocorrência de danos em virtude do tratamento de dados pessoais; IX – não discriminação: impossibilidade de realização do tratamento para fins discriminatórios ilícitos ou abusivos; X – responsabilização e prestação de contas: demonstração, pelo agente, da adoção de medidas eficazes e capazes de comprovar a observância e o cumprimento das normas de proteção de dados pessoais e, inclusive, da eficácia dessas medidas. | G22: CAPÍTULO I - DISPOSIÇÕES PRELIMINARES | H22: Não existe. | I22: Não iniciado | J22: Não aderente | K22: N/A
D23: Se a pergunta principal for Sim S/N | E23: O processo de Privacy by Design está documentado ? | F23: Art. 6º As atividades de tratamento de dados pessoais deverão observar a boa-fé e os seguintes princípios: I - finalidade: realização do tratamento para propósitos legítimos, específicos, explícitos e informados ao titular, sem possibilidade de tratamento posterior de forma incompatível com essas finalidades; II - adequação: compatibilidade do tratamento com as finalidades informadas ao titular, de acordo com o contexto do tratamento; III - necessidade: limitação do tratamento ao mínimo necessário para a realização de suas finalidades, com abrangência dos dados pertinentes, proporcionais e não excessivos em relação às finalidades do tratamento de dados; IV - livre acesso: garantia, aos titulares, de consulta facilitada e gratuita sobre a forma e a duração do tratamento, bem como sobre a integralidade de seus dados pessoais; V - qualidade dos dados: garantia, aos titulares, de exatidão, clareza, relevância e atualização dos dados, de acordo com a necessidade e para o cumprimento da finalidade de seu tratamento; VI - transparência: garantia, aos titulares, de informações claras, precisas e facilmente acessíveis sobre a realização do tratamento e os respectivos agentes de tratamento, observados os segredos comercial e industrial; VII - segurança: utilização de medidas técnicas e administrativas aptas a proteger os dados pessoais de acessos não autorizados e de situações acidentais ou ilícitas de destruição, perda, alteração, comunicação ou difusão; VIII - prevenção: adoção de medidas para prevenir a ocorrência de danos em virtude do tratamento de dados pessoais; IX - não discriminação: impossibilidade de realização do tratamento para fins discriminatórios ilícitos ou abusivos; X - responsabilização e prestação de contas: demonstração, pelo agente, da adoção de medidas eficazes e capazes de comprovar a observância e o cumprimento das normas de proteção de dados pessoais e, inclusive, da eficácia dessas medidas. | G23: CAPÍTULO I - DISPOSIÇÕES PRELIMINARES | H23: Não existe. | I23: Não iniciado | J23: Não aderente | K23: N/A
B24: 6 | C24: DPIA | D24: S/N | E24: A organização emite atualmente algum tipo de relatório de impacto de proteção de dados pessoais - DPIA (Data Protection & Impact Assessment)? | F24: Art. 38. A autoridade nacional poderá determinar ao controlador que elabore relatório de impacto à proteção de dados pessoais, inclusive de dados sensíveis, referente a suas operações de tratamento de dados, nos termos de regulamento, observados os segredos comercial e industrial. Parágrafo único. Observado o disposto no caput deste artigo, o relatório deverá conter, no mínimo, a descrição dos tipos de dados coletados, a metodologia utilizada para a coleta e para a garantia da segurança das informações e a análise do controlador com relação a medidas, salvaguardas e mecanismos de mitigação de risco adotados. | G24: CAPÍTULO VI DOS AGENTES DE TRATAMENTO DE DADOS PESSOAIS Seção I Do Controlador e do Operador | H24: Não | I24: Não iniciado | J24: Não aderente | K24: Ao utilizar a base legal do legitimo interesse ou em casos que possam gerar risco ao titular, ou ainda quando solicitado pela ANPD a Empresa Beta deverá elaborar o Relatório de Impacto.
D25: Se a pergunta anterior for Sim S/N | E25: O processo de DPIA (Data Protection & Impact Assessment) considera o princípio da boa fé e os 10 princípios de privacidade ? | F25: Art. 6º As atividades de tratamento de dados pessoais deverão observar a boa-fé e os seguintes princípios: I - finalidade: realização do tratamento para propósitos legítimos, específicos, explícitos e informados ao titular, sem possibilidade de tratamento posterior de forma incompatível com essas finalidades; II - adequação: compatibilidade do tratamento com as finalidades informadas ao titular, de acordo com o contexto do tratamento; III - necessidade: limitação do tratamento ao mínimo necessário para a realização de suas finalidades, com abrangência dos dados pertinentes, proporcionais e não excessivos em relação às finalidades do tratamento de dados; IV - livre acesso: garantia, aos titulares, de consulta facilitada e gratuita sobre a forma e a duração do tratamento, bem como sobre a integralidade de seus dados pessoais; V - qualidade dos dados: garantia, aos titulares, de exatidão, clareza, relevância e atualização dos dados, de acordo com a necessidade e para o cumprimento da finalidade de seu tratamento; VI - transparência: garantia, aos titulares, de informações claras, precisas e facilmente acessíveis sobre a realização do tratamento e os respectivos agentes de tratamento, observados os segredos comercial e industrial; VII - segurança: utilização de medidas técnicas e administrativas aptas a proteger os dados pessoais de acessos não autorizados e de situações acidentais ou ilícitas de destruição, perda, alteração, comunicação ou difusão; VIII - prevenção: adoção de medidas para prevenir a ocorrência de danos em virtude do tratamento de dados pessoais; IX - não discriminação: impossibilidade de realização do tratamento para fins discriminatórios ilícitos ou abusivos; X - responsabilização e prestação de contas: demonstração, pelo agente, da adoção de medidas eficazes e capazes de comprovar a observância e o cumprimento das normas de proteção de dados pessoais e, inclusive, da eficácia dessas medidas. | G25: CAPÍTULO I - DISPOSIÇÕES PRELIMINARES | H25: Não existe. | I25: Não iniciado | J25: Não aderente | K25: N/A
D26: Se a pergunta principal for Sim | E26: O processo de DPIA está documentado? Com qual frequência o processo é conduzido? Para qual escopo ? | F26: Art. 38. A autoridade nacional poderá determinar ao controlador que elabore relatório de impacto à proteção de dados pessoais, inclusive de dados sensíveis, referente a suas operações de tratamento de dados, nos termos de regulamento, observados os segredos comercial e industrial. Parágrafo único. Observado o disposto no caput deste artigo, o relatório deverá conter, no mínimo, a descrição dos tipos de dados coletados, a metodologia utilizada para a coleta e para a garantia da segurança das informações e a análise do controlador com relação a medidas, salvaguardas e mecanismos de mitigação de risco adotados. | G26: CAPÍTULO VI DOS AGENTES DE TRATAMENTO DE DADOS PESSOAIS Seção I Do Controlador e do Operador | H26: Não existe. | I26: Não iniciado | J26: Não aderente | K26: N/A
D27: S/N | E27: Um relatório de impacto a proteção dos dados foi gerado para os casos em que o legítimo interesse foi adotado como base legal ? | F27: Art 10 § 3º A autoridade nacional poderá solicitar ao controlador relatório de impacto à proteção de dados pessoais, quando o tratamento tiver como fundamento seu interesse legítimo, observados os segredos comercial e industrial. | G27: CAPÍTULO II - DO TRATAMENTO DE DADO S PESSOAIS Seção I Dos Requisitos para o Tratamen to de Dados Pessoais | H27: Não foi elaborado nenhum Relatório de Impacto | I27: Não iniciado | J27: Não aderente | K27: N/A
B28: 7 | C28: Direito dos titulares dos dados | D28: S/N | E28: Existe um processo/sistema que permite o atendimento às requisições do titular (acesso, confirmação, correção,anonimização,bloqueio,eliminação,portabilidade e revogação de consentimento)? | F28: Art. 18. O titular dos dados pessoais tem direito a obter do controlador, em relação aos dados do titular por ele tratados, a qualquer momento e mediante requisição: I - confirmação da existência de tratamento; II - acesso aos dados; III - correção de dados incompletos, inexatos ou desatualizados; IV - anonimização, bloqueio ou eliminação de dados desnecessários, excessivos ou tratados em desconformidade com o disposto nesta Lei; V - portabilidade dos dados a outro fornecedor de serviço ou produto, mediante requisição expressa e observados os segredos comercial e industrial, de acordo com a regulamentação do órgão controlador; VI - eliminação dos dados pessoais tratados com o consentimento do titular, exceto nas hipóteses previstas no art. 16 desta Lei; VII - informação das entidades públicas e privadas com as quais o controlador realizou uso compartilhado de dados; VIII - informação sobre a possibilidade de não fornecer consentimento e sobre as consequências da negativa; IX - revogação do consentimento, nos termos do § 5º do art. 8º desta Lei. | G28: CAPÍTULO III DOS DIREITOS DO TI TULAR | H28: Inexiste procedimento para atendimento aos Titulares. | I28: Não iniciado | J28: Não aderente | K28: É necessário estabelecer um procedimento para atendimento das demandas dos titulares.
D29: Se a pergunta anterior for Sim S/N | E29: O processo/sistema permite que o titular tenha acesso facilitado às informações sobre o tratamento de seus dados (finalidade, forma, duração do tratamento, dados do controlador, uso compartilhado, responsabilidade e demais direitos do titular) de forma clara e simplificada? | F29: Art. 9º O titular tem direito ao acesso facilitado às informações sobre o tratamento de seus dados, que deverão ser disponibilizadas de forma clara, adequada e ostensiva acerca de, entre outras características previstas em regulamentação para o atendimento do princípio do livre acesso: I - finalidade específica do tratamento; II - forma e duração do tratamento, observados os segredos comercial e industrial; III - identificação do controlador; IV - informações de contato do controlador; V - informações acerca do uso compartilhado de dados pelo controlador e a finalidade; VI - responsabilidades dos agentes que realizarão o tratamento; e VII - direitos do titular, com menção explícita aos direitos contidos no art. 18 desta Lei. | G29: CAPÍTULO II - DO TRATAMENTO DE DADOS PESSOAIS - Seção I Dos Requisitos para o Tratamento de Dados Pessoais | H29: Inexiste procedimento para atendimento aos Titulares. | I29: Não iniciado | J29: Não aderente | K29: É necessário estabelecer um procedimento para atendimento das demandas dos titulares.
D30: S/N | E30: Existe um prazo para resposta às requisições dos titulares relacionadas à existênia ou acesso a seus dados pessoais? | F30: Art. 19. A confirmação de existência ou o acesso a dados pessoais serão providenciados, mediante requisição do titular: I - em formato simplificado, imediatamente; ou II - por meio de declaração clara e completa, que indique a origem dos dados, a inexistência de registro, os critérios utilizados e a finalidade do tratamento, observados os segredos comercial e industrial, fornecida no prazo de até 15 (quinze) dias, contado da data do requerimento do titular. § 1º Os dados pessoais serão armazenados em formato que favoreça o exercício do direito de acesso. § 2º As informações e os dados poderão ser fornecidos, a critério do titular: I - por meio eletrônico, seguro e idôneo para esse fim; ou II - sob forma impressa. | G30: CAPÍTULO III - DOS DIREITOS DO TITULAR | H30: Inexiste procedimento para resposta aos Titulares. | I30: Não iniciado | J30: Não aderente | K30: Elaboração de procedimento para atender as demandas do colaborador, inclusive com indicação de prazo de resposta.
D31: S/N | E31: Existe um procedimento padrão para atendimento às requisições dos titulares caso o atendimento não possa ser realizado de forma imediata? | F31: Art. 18 § 4º Em caso de impossibilidade de adoção imediata da providência de que trata o § 3º deste artigo, o controlador enviará ao titular resposta em que poderá: I - comunicar que não é agente de tratamento dos dados e indicar, sempre que possível, o agente; ou II - indicar as razões de fato ou de direito que impedem a adoção imediata da providência | G31: CAPÍTULO III - DOS DIREITOS DO TITULAR | H31: Inexiste procedimento para atendimento aos Titulares. | I31: Não iniciado | J31: Não aderente | K31: Definir um canal e um processo para atender as demandas do titular de dados.
D32: S/N | E32: O processo de correção, eliminação, anonimização e bloqueio de dados, originado da requisição de um titular, foi desenhado de modo a acionar todas as empresas com as quais os dados do titular foram compartilhados? | F32: Art. 18. § 6º O responsável deverá informar de maneira imediata aos agentes de tratamento com os quais tenha realizado uso compartilhado de dados a correção, a eliminação, a anonimização ou o bloqueio dos dados, para que repitam idêntico procedimento. | G32: CAPÍTULO III - DOS DIREITOS DO TITULAR | H32: Inexiste procedimento para atendimento aos Titulares. | I32: Não iniciado | J32: Não aderente | K32: Definir um canal e um processo para atender as demandas do titular de dados.
D33: S/N | E33: Existem decisões tomadas com base em tratamentos automatizados? | F33: Art. 20. O titular dos dados tem direito a solicitar revisão, por pessoa natural, de decisões tomadas unicamente com base em tratamento automatizado de dados pessoais que afetem seus interesses, inclusive de decisões destinadas a definir o seu perfil pessoal, profissional, de consumo e de crédito ou os aspectos de sua personalidade. § 1º O controlador deverá fornecer, sempre que solicitadas, informações claras e adequadas a respeito dos critérios e dos procedimentos utilizados para a decisão automatizada, observados os segredos comercial e industrial. | G33: CAPÍTULO III - DOS DIREITOS DO TITULAR | H33: Não | I33: Não iniciado | J33: Não aderente | K33: N/A
B34: 8 | C34: Tratamento dos dados pessoais - Legitimação de uso de dados | D34: S/N | E34: A organização possui um inventário de dados pessoais com a indicação das respectivas bases legais (justificativas) para legitimação do uso dos dados? | F34: Art. 7º O tratamento de dados pessoais somente poderá ser realizado nas seguintes hipóteses: I - mediante o fornecimento de consentimento pelo titular; II - para o cumprimento de obrigação legal ou regulatória pelo controlador; III - pela administração pública, para o tratamento e uso compartilhado de dados necessários à execução de políticas públicas previstas em leis e regulamentos ou respaldadas em contratos, convênios ou instrumentos congêneres, observadas as disposições do Capítulo IV desta Lei; IV - para a realização de estudos por órgão de pesquisa, garantida, sempre que possível, a anonimização dos dados pessoais; V - quando necessário para a execução de contrato ou de procedimentos preliminares relacionados a contrato do qual seja parte o titular, a pedido do titular dos dados; VI - para o exercício regular de direitos em processo judicial, administrativo ou arbitral, esse último nos termos da Lei nº 9.307, de 23 de setembro de 1996 (Lei de Arbitragem); VII - para a proteção da vida ou da incolumidade física do titular ou de terceiro; VIII - para a tutela da saúde, em procedimento realizado por profissionais da área da saúde ou por entidades sanitárias; IX - quando necessário para atender aos interesses legítimos do controlador ou de terceiro, exceto no caso de prevalecerem direitos e liberdades fundamentais do titular que exijam a proteção dos dados pessoais; ou X - para a proteção do crédito, inclusive quanto ao disposto na legislação pertinente. § 1º Nos casos de aplicação do disposto nos incisos II e III do caput deste artigo e excetuadas as hipóteses previstas no art. 4º desta Lei, o titular será informado das hipóteses em que será admitido o tratamento de seus dados. § 2º A forma de disponibilização das informações previstas no § 1º e no inciso I do caput do art. 23 desta Lei poderá ser especificada pela autoridade nacional. | G34: CAPÍTULO II - DO TRATAMENTO DE DADO S PESSOAIS Seção I Dos Requisitos para o Tratamen to de Dados Pessoais | H34: O Mapeamento de Dados está em processo de finalização. | I34: Em andamento | J34: Parcialmente aderente | K34: O mapeamento de dados é um documento extremamente importante para a Empresa Beta e a avaliação do ciclo de dados permite a adequação à LGPD em conformidade com o que prevê a Lei.
B35: 9 | C35: Contratos | D35: S/N | E35: Os contratos celebrados pela organização com clientes, fornecedores, empregados, prestadores de serviço, etc, possuem cláusula relativa ao tratamento de dados pessoais se e quando aplicável? | F35: Art. 7º O tratamento de dados pessoais somente poderá ser realizado nas seguintes hipóteses: V - quando necessário para a execução de contrato ou de procedimentos preliminares relacionados a contrato do qual seja parte o titular, a pedido do titular dos dados. | G35: CAPÍTULO II - DO TRATAMENTO DE DADO S PESSOAIS Seção I Dos Requisitos para o Tratamen to de Dados Pessoais | H35: Necessário avaliar os contratos celebrados entre a Empresa Beta e terceiros. | I35: Não iniciado | J35: Não aderente | K35: Avaliação dos Contratos de terceiros e indicação da necessidade de inclusão de cláusula de proteção de dados quando aplicável
B36: 10 | C36: Tratamento dos dados pessoais - Legitimação de uso de dados | D36: S/N | E36: O uso do legítimo interesse para legitimação de dados limita-se as hipóteses apresentadas abaixo: | F36: Art. 10. O legítimo interesse do controlador somente poderá fundamentar tratamento de dados pessoais para finalidades legítimas, consideradas a partir de situações concretas, que incluem, mas não se limitam a: I – apoio e promoção de atividades do controlador; II – proteção, em relação ao titular, do exercício regular de seus direitos ou prestação de serviços que o beneficiem, respeitadas as legítimas expectativas dele e os direitos e liberdades fundamentais, nos termos desta Lei. § 1º Quando o tratamento for baseado no legítimo interesse do controlador, somente os dados pessoais estritamente necessários para a finalidade pretendida poderão ser tratados. § 2º O controlador deverá adotar medidas para garantir a transparência do tratamento de dados baseado em seu legítimo interesse. § 3º A autoridade nacional poderá solicitar ao controlador relatório de impacto à proteção de dados pessoais, quando o tratamento tiver como fundamento seu interesse legítimo, observados os segredos comercial e industrial. | G36: CAPÍTULO II - DO TRATAMENTO DE DADO S PESSOAIS Seção I Dos Requisitos para o Tratamen to de Dados Pessoais
D37: Checkbox | E37: I – apoio e promoção de atividades do controlador; | H37: Sim | I37: Em andamento | J37: Parcialmente aderente | K37: Necessário elaborar Teste de Balanceamento para verificar se o interesse legitimo da Empresa Beta é adequado.
E38: II – proteção, em relação ao titular, do exercício regular de seus direitos ou prestação de serviços que o beneficiem, respeitadas as legítimas expectativas dele e os direitos e liberdades fundamentais, nos termos desta Lei. | H38: Sim | I38: Em andamento | J38: Parcialmente aderente | K38: Necessário elaborar Teste de Balanceamento para verificar se o interesse legitimo da Empresa Beta é adequado.
B39: 11 | C39: Tratamento dos dados pessoais - Legitimação de uso de dados | D39: S/N | E39: O uso de legítimo interesse para legitimação de dados está documentado pelo controlador e operador? | F39: Art. 37. O controlador e o operador devem manter registro das operações de tratamento de dados pessoais que realizarem, especialmente quando baseado no legítimo interesse. | G39: CAPÍTULO VI - DOS AGENTES DE TRATAMENTO D E DADOS PESSOAIS Seção I Do Controlador e do Operador | H39: Não | I39: Não iniciado | J39: Não aderente | K39: Necessário elaborar Teste de Balanceamento para verificar se o interesse legitimo da Empresa Beta é adequado.
B40: 12 | C40: Tratamento dos dados pessoais - Dados públicos | D40: S/N | E40: A organização realiza tratamento de dados pessoais cujo acesso é público? | F40: Art. 7 § 3º O tratamento de dados pessoais cujo acesso é público deve considerar a finalidade, a boa-fé e o interesse público que justificaram sua disponibilização. | G40: CAPÍTULO II - DO TRATAMENTO DE DADO S PESSOAIS Seção I Dos Requisitos para o Tratamen to de Dados Pessoais | H40: Sim | I40: Não iniciado | J40: Parcialmente aderente | K40: Necessário validar se o uso de dados públicos é legitmo.
D41: Se a pergunta anterior for Sim S/N | E41: O tratamento dos dados pessoais de acesso público consideraram a finalidade, a boa-fé e o interesse público que justificaram a sua disponibilização? | F41: Art. 7 § 3º O tratamento de dados pessoais cujo acesso é público deve considerar a finalidade, a boa-fé e o interesse público que justificaram sua disponibilização. | G41: CAPÍTULO II - DO TRATAMENTO DE DADO S PESSOAIS Seção I Dos Requisitos para o Tratamen to de Dados Pessoais | H41: Necessário validar. | I41: Não iniciado | J41: Parcialmente aderente | K41: Necessário validar se o uso de dados públicos é legitmo.
B42: 13 | C42: Tratamento de dados pessoais - Obtenção / Revogação do Consentimento | D42: S/N | E42: A organização realiza tratamento de dados pessoais mediante o fornecimento de consentimento pelo titular? | F42: Art. 7º O tratamento de dados pessoais somente poderá ser realizado nas seguintes hipóteses: I - mediante o fornecimento de consentimento pelo titular; II - para o cumprimento de obrigação legal ou regulatória pelo controlador; III - pela administração pública, para o tratamento e uso compartilhado de dados necessários à execução de políticas públicas previstas em leis e regulamentos ou respaldadas em contratos, convênios ou instrumentos congêneres, observadas as disposições do Capítulo IV desta Lei; IV - para a realização de estudos por órgão de pesquisa, garantida, sempre que possível, a anonimização dos dados pessoais; V - quando necessário para a execução de contrato ou de procedimentos preliminares relacionados a contrato do qual seja parte o titular, a pedido do titular dos dados; VI - para o exercício regular de direitos em processo judicial, administrativo ou arbitral, esse último nos termos da Lei nº 9.307, de 23 de setembro de 1996 (Lei de Arbitragem); VII - para a proteção da vida ou da incolumidade física do titular ou de terceiro; VIII - para a tutela da saúde, em procedimento realizado por profissionais da área da saúde ou por entidades sanitárias; IX - quando necessário para atender aos interesses legítimos do controlador ou de terceiro, exceto no caso de prevalecerem direitos e liberdades fundamentais do titular que exijam a proteção dos dados pessoais; ou X - para a proteção do crédito, inclusive quanto ao disposto na legislação pertinente. § 1º Nos casos de aplicação do disposto nos incisos II e III do caput deste artigo e excetuadas as hipóteses previstas no art. 4º desta Lei, o titular será informado das hipóteses em que será admitido o tratamento de seus dados. § 2º A forma de disponibilização das informações previstas no § 1º e no inciso I do caput do art. 23 desta Lei poderá ser especificada pela autoridade nacional. | G42: CAPÍTULO II - DO TRATAMENTO DE DADO S PESSOAIS Seção I Dos Requisitos para o Tratamen to de Dados Pessoais | H42: Não | I42: Finalizado | J42: N/A | K42: N/A
D43: Se a pergunta anterior for Sim S/N | E43: O consentimento é obtido de forma livre (demonstra a manifestação de vontade do titular) ? | F43: Art. 8º O consentimento previsto no inciso I do art. 7º desta Lei deverá ser fornecido por escrito ou por outro meio que demonstre a manifestação de vontade do titular. cláusulas contratuais. § 2º Cabe ao controlador o ônus da prova de que o consentimento foi obtido em conformidade com o disposto nesta Lei. § 3º É vedado o tratamento de dados pessoais mediante vício de consentimento. § 4º O consentimento deverá referir-se a finalidades determinadas, e as autorizações genéricas para o tratamento de dados pessoais serão nulas. | G43: CAPÍTULO II - DO TRATAMENTO DE DADO S PESSOAIS Seção I Dos Requisitos para o Tratamen to de Dados Pessoais | H43: Não aplicável a realidade da Empresa Beta | I43: Finalizado | J43: N/A | K43: N/A
D44: Se a pergunta principal for Sim S/N | E44: Existe a possibilidade do titular dos dados revogar o consentimento a qualquer momento ? | F44: Art. 8. § 5º O consentimento pode ser revogado a qualquer momento mediante manifestação expressa do titular, por procedimento gratuito e facilitado, ratificados os tratamentos realizados sob amparo do consentimento anteriormente manifestado enquanto não houver requerimento de eliminação, nos termos do inciso VI do caput do art. 18 desta Lei. | G44: CAPÍTULO II - DO TRATAMENTO DE DADO S PESSOAIS Seção I Dos Requisitos para o Tratamen to de Dados Pessoais | H44: Não | I44: Finalizado | J44: N/A | K44: N/A
...

Sheet Analítico
B2: Analítico
B5: Agentes de tratamento de dados | D5: 0 | E5: DPIA | G5: =COUNTIF(F7:F9,"Aderente")/COUNTA(F7:F9) -> 0 | H5: DPO | J5: =COUNTIF(I7:I8,"Aderente")/COUNTA(I7:I8) -> 0
B6: Exigência | C6: Adesão | D6: 1 | E6: Exigência | F6: Adesão | G6: =COUNTIF(F7:F9,"Não Aderente")/COUNTA(F7:F9) -> 1 | H6: Exigência | I6: Adesão | J6: =COUNTIF(I7:I8,"Não Aderente")/COUNTA(I7:I8) -> 1
B7: Existência de processo | C7: =Controles!J93 -> Não aderente | D7: 0 | E7: Considera 10 princípios da boa-fé | F7: =Controles!J25 -> Não aderente | G7: =COUNTIF(F7:F9,"Parcialmente Aderente")/COUNTA(F7:F9) -> 0 | H7: Nomeação do DPO e divulgação | I7: Não aderente | J7: =COUNTIF(I7:I8,"Parcialmente Aderentemente Aderente")/COUNTA(I7:I8) -> 0
D8: 0 | E8: Processo documentado | F8: =Controles!J26 -> Não aderente | G8: =COUNTIF(F7:F9,"N/A")/COUNTA(F7:F9) -> 0 | H8: Definição de responsabilidades | I8: Não aderente | J8: =COUNTIF(I7:I8,"N/A")/COUNTA(I7:I8) -> 0
B9: Direito dos titulares dos dados | D9: 0 | E9: Geração de relatório de impacto | F9: =Controles!J27 -> Não aderente
B10: Exigência | C10: Adesão | D10: 0.5 | H10: Programa de governança em privacidade | J10: =COUNTIF(I12:I13,"Aderente")/COUNTA(I12:I13) -> 0
B11: Existência de processo de emissão de requisição | C11: =Controles!J28 -> Não aderente | D11: 0.33333333 | E11: Gestão de incidentes de privacidade | G11: =COUNTIF(F13:F13,"Aderente")/COUNTA(F13:F13) -> 0 | H11: Exigência | I11: Adesão | J11: =COUNTIF(I12:I13,"Não Aderente")/COUNTA(I12:I13) -> 1
B12: Usuário possui detalhes da forma de tratamento dos dados | C12: =Controles!J29 -> Não aderente | D12: 0.16666667 | E12: Exigência | F12: Adesão | G12: =COUNTIF(F13:F13,"Não Aderente")/COUNTA(F13:F13) -> 1 | H12: Existência do programa | I12: =Controles!J111 -> Não aderente | J12: =COUNTIF(I12:I13,"Parcialmente Aderentemente Aderente")/COUNTA(I12:I13) -> 0
B13: Processo de resposta impresso/eletrônico | C13: =Controles!J30 -> Não aderente | E13: Existência do processo e documentação | F13: =Controles!J107 -> Não aderente | G13: =COUNTIF(F13:F13,"Parcialmente Aderente")/COUNTA(F13:F13) -> 0 | H13: Demonstração de efetividade | I13: =Controles!J118 -> Não aderente | J13: =COUNTIF(I12:I13,"N/A")/COUNTA(I12:I13) -> 0
B14: Existência de processo de resposta | C14: =Controles!J31 -> Não aderente | G14: =COUNTIF(F13:F13,"N/A")/COUNTA(F13:F13) -> 0
B15: O processo aciona todas as empresas com as quais os dados foram compartilhados | C15: =Controles!J32 -> Não aderente | E15: Privacy by Design | G15: =COUNTIF(F17:F18,"Aderente")/COUNTA(F17:F18) -> 0 | H15: Término do tratamento de dados | J15: =COUNTIF(I17:I18,"Aderente")/COUNTA(I17:I18) -> 0
B16: Existência de decisões baseadas em tratamentos automatizados | C16: =Controles!J33 -> Não aderente | E16: Exigência | F16: Adesão | G16: =COUNTIF(F17:F18,"Não Aderente")/COUNTA(F17:F18) -> 1 | H16: Exigência | I16: Adesão | J16: =COUNTIF(I17:I18,"Não Aderente")/COUNTA(I17:I18) -> 0
E17: Considera os 10 princípios da boa-fé | F17: =Controles!J22 -> Não aderente | G17: =COUNTIF(F17:F18,"Parcialmente Aderente")/COUNTA(F17:F18) -> 0 | H17: Existência de prazo de retenção | I17: =Controles!J71 -> 0 | J17: =COUNTIF(I17:I18,"Parcialmente Aderentemente Aderente")/COUNTA(I17:I18) -> 0
B18: Segurança da Informação | D18: 0 | E18: Processo documentado | F18: =Controles!J23 -> Não aderente | G18: =COUNTIF(F17:F18,"N/A")/COUNTA(F17:F18) -> 0 | H18: Existência de dados pessoais com prazo de retenção indeterminado | I18: =Controles!J77 -> 0 | J18: =COUNTIF(I17:I18,"N/A")/COUNTA(I17:I18) -> 0
B19: Exigência | C19: Adesão | D19: 0.6
B20: Dados armazenados em sistemas com controle de acesso/Revisão de acesso | C20: =Controles!J98 -> Aderente | D20: 0.4 | E20: Transferência internacional de dados | G20: =COUNTIF(F22:F22,"Aderente")/COUNTA(F22:F22) -> 0 | H20: Tratamento de Dados Pessoais - Compartilhamento de dados | J20: =COUNTIF(I22:I22,"Aderente")/COUNTA(I22:I22) -> 0
B21: Backup periódico de dados pessoais/PCN e DRP | C21: =Controles!J101 -> Parcialmente aderente | D21: 0 | E21: Exigência | F21: Adesão | G21: =COUNTIF(F22:F22,"Não Aderente")/COUNTA(F22:F22) -> 1 | H21: Exigência | I21: Adesão | J21: =COUNTIF(I22:I22,"Não Aderente")/COUNTA(I22:I22) -> 1
B22: Dados pessoais protegidos por técnicas e processos que previnem sua alteração e perda de integridade | C22: =Controles!J103 -> Não aderente | E22: Dados pessoais transferidos para outros países | F22: =Controles!J82 -> Não aderente | G22: =COUNTIF(F22:F22,"Parcialmente Aderente")/COUNTA(F22:F22) -> 0 | H22: Informação ao titular sobre compartilhamento de dados com outros controladores | I22: =Controles!J81 -> Não aderente | J22: =COUNTIF(I22:I22,"Parcialmente Aderentemente Aderente")/COUNTA(I22:I22) -> 0
B23: Dados pessoais protegidos por criptografia | C23: =Controles!J105 -> Não aderente | G23: =COUNTIF(F22:F22,"N/A")/COUNTA(F22:F22) -> 0 | J23: =COUNTIF(I22:I22,"N/A")/COUNTA(I22:I22) -> 0
B24: Processo que garante que o operador possua processos de segurança da informação | C24: =Controles!J106 -> Não aderente | E24: Tratamento de Dados Pessoais - Legitimação de uso de dados | G24: =COUNTIF(F26:F28,"Aderente")/COUNTA(F26:F28) -> 0 | H24: Tratamento de Dados Pessoais - Obtenção de Consentimento | J24: =COUNTIF(I26:I26,"Aderente")/COUNTA(I26:I26) -> 0
E25: Exigência | F25: Adesão | G25: =COUNTIF(F26:F28,"Não Aderente")/COUNTA(F26:F28) -> 0.33333333 | H25: Exigência | I25: Adesão | J25: =COUNTIF(I26:I26,"Não Aderente")/COUNTA(I26:I26) -> 0
B26: Tratamento de Dados Pessoais - Dados Públicos | D26: 0 | E26: Possui inventário de dados pessoais | F26: =Controles!J34 -> Parcialmente aderente | G26: =COUNTIF(F26:F28,"Parcialmente Aderente")/COUNTA(F26:F28) -> 0.33333333 | H26: Obtido de forma livre | I26: =Controles!J43 -> N/A | J26: =COUNTIF(I26:I26,"Parcialmente Aderentemente Aderente")/COUNTA(I26:I26) -> 0
B27: Exigência | C27: Adesão | D27: 1 | E27: Uso de legítimo interesse limitado | F27: =Controles!J36 -> 0 | G27: =COUNTIF(F26:F28,"N/A")/COUNTA(F26:F28) -> 0 | J27: =COUNTIF(I26:I26,"N/A")/COUNTA(I26:I26) -> 1
B28: Considera a finalidade, boa-fé e interesse público | C28: =Controles!J40 -> Parcialmente aderente | D28: 0 | E28: Documentação pelo controlador e operador | F28: =Controles!J39 -> Não aderente | H28: Tratamento de Dados Pessoais - Revogação de Consentimento | J28: =COUNTIF(I30:I30,"Aderente")/COUNTA(I30:I30) -> 0
D29: 0 | H29: Exigência | I29: Adesão | J29: =COUNTIF(I30:I30,"Não Aderente")/COUNTA(I30:I30) -> 0
E30: Tratamento de Dados Pessoais - Atualização de Consentimento | G30: =COUNTIF(F32:F32,"Aderente")/COUNTA(F32:F32) -> 0 | H30: Revogação a qualquer momento | I30: =Controles!J44 -> N/A | J30: =COUNTIF(I30:I30,"Parcialmente Aderentemente Aderente")/COUNTA(I30:I30) -> 0
B31: Tratamento de Dados Pessoais - Tratamento de dados obrigatório | E31: Exigência | F31: Adesão | G31: =COUNTIF(F32:F32,"Não Aderente")/COUNTA(F32:F32) -> 1 | J31: =COUNTIF(I30:I30,"N/A")/COUNTA(I30:I30) -> 1
B32: Exigência | C32: Adesão | D32: 0 | E32: Existência do processo | F32: =Controles!J45 -> Não aderente | G32: =COUNTIF(F32:F32,"Parcialmente Aderente")/COUNTA(F32:F32) -> 0 | H32: Tratamento de Dados Pessoais - Poder Públicos
B33: Condição obrigatória | C33: =Controles!J48 -> Parcialmente aderente | D33: 0 | G33: =COUNTIF(F32:F32,"N/A")/COUNTA(F32:F32) -> 0 | H33: Exigência | I33: Adesão | J33: =COUNTIF(I34:I41,"Aderente")/COUNTA(I34:I41) -> 0
D34: 1 | E34: Tratamento de Dados Pessoais Sensíveis - Sem Consentimento | G34: =COUNTIF(F36:F36,"Aderente")/COUNTA(F36:F36) -> 0 | H34: Dados coletados necessários | I34: =Controles!J119 -> N/A | J34: =COUNTIF(I34:I41,"Não Aderente")/COUNTA(I34:I41) -> 0
B35: Tratamento de Dados Pessoais Sensíveis - Anonimização | D35: 0 | E35: Exigência | F35: Adesão | G35: =COUNTIF(F36:F36,"Não Aderente")/COUNTA(F36:F36) -> 0 | H35: DPO nomeado por órgão público | I35: =Controles!J120 -> N/A | J35: =COUNTIF(I34:I41,"Parcialmente Aderentemente Aderente")/COUNTA(I34:I41) -> 0
B36: Exigência | C36: Adesão | D36: 0 | E36: Tratamento de dados sensíveis limitado às condições impostas | F36: =Controles!J52 -> 0 | G36: =COUNTIF(F36:F36,"Parcialmente Aderente")/COUNTA(F36:F36) -> 0 | H36: Formato interoperável e estruturado de dados | I36: =Controles!J121 -> N/A | J36: =COUNTIF(I34:I41,"N/A")/COUNTA(I34:I41) -> 1
B37: Dados sensíveis são anonimizados | C37: =Controles!J62 -> N/A | D37: 0 | G37: =COUNTIF(F36:F36,"N/A")/COUNTA(F36:F36) -> 0 | H37: Uso compartilhado de dados pessoais atende finalidades específicas | I37: =Controles!J122 -> N/A
D38: 1 | E38: Tratamento de Dados Pessoais Sensíveis - Compartilhamento entre controladores | G38: =COUNTIF(F40:F40,"Aderente")/COUNTA(F40:F40) -> 0 | H38: Transferência de dados para empresas privadas | I38: =Controles!J123 -> N/A
B39: Tratamento de Dados Pessoais Sensíveis - Consentimento | D39: 0 | E39: Exigência | F39: Adesão | G39: =COUNTIF(F40:F40,"Não Aderente")/COUNTA(F40:F40) -> 1 | H39: Contratos, convênios e instrumentos congêneres são comunicados à autoridade nacional | I39: =Controles!J124 -> N/A
B40: Exigência | C40: Adesão | D40: 1 | E40: Existe compartilhamento com outros controladores | F40: =Controles!J60 -> Não aderente | G40: =COUNTIF(F40:F40,"Parcialmente Aderente")/COUNTA(F40:F40) -> 0 | H40: Comunicação de dados pessoais de PJ de direito público à pessoa de direito privado é informado à autoridade nacional | I40: =Controles!J125 -> N/A
B41: Consentimento específico e destacado | C41: =Controles!J50 -> N/A | D41: 0 | G41: =COUNTIF(F40:F40,"N/A")/COUNTA(F40:F40) -> 0
D42: 0 | E42: Tratamento de Dados Pessoais Sensíveis - Estudos e Pesquisa de Saúde Pública | G42: =COUNTIF(F44:F44,"Aderente")/COUNTA(F44:F44) -> 0
B43: Tratamento de Dados Pessoais Sensíveis - Crianças e Adolescentes | D43: 0 | E43: Exigência | F43: Adesão | G43: =COUNTIF(F44:F44,"Não Aderente")/COUNTA(F44:F44) -> 0
...

Sheet Status da Análise
